1681927195.450420 2023-04-19 17:59:55 MainProcess-136941 MainThread-140030062446400 parsl.dataflow.dflow:86 __init__ DEBUG: Starting DataFlowKernel with config
Config(
    app_cache=True, 
    checkpoint_files=None, 
    checkpoint_mode=None, 
    checkpoint_period=None, 
    executors=[HighThroughputExecutor(
        address='polaris-login-01', 
        address_probe_timeout=None, 
        available_accelerators=['0', '1', '2', '3'], 
        cores_per_worker=1.0, 
        cpu_affinity='alternating', 
        heartbeat_period=30, 
        heartbeat_threshold=120, 
        interchange_port_range=(55000, 56000), 
        label='htex_PBS', 
        launch_cmd='process_worker_pool.py {debug} {max_workers} -a {addresses} -p {prefetch_capacity} -c {cores_per_worker} -m {mem_per_worker} --poll {poll_period} --task_port={task_port} --result_port={result_port} --logdir={logdir} --block_id={{block_id}} --hb_period={heartbeat_period} {address_probe_timeout_string} --hb_threshold={heartbeat_threshold} --cpu-affinity {cpu_affinity} --available-accelerators {accelerators}', 
        managed=True, 
        max_workers=4, 
        mem_per_worker=None, 
        poll_period=10, 
        prefetch_capacity=0, 
        provider=PBSProProvider(
            account='TFXcan', 
            channel=LocalChannel(
                envs={}, 
                script_dir=None, 
                userhome='/lus/grand/projects/covid-ct/imlab/users/shared/enformer_pipeline'
            ), 
            cmd_timeout=120, 
            cpus_per_node=64, 
            init_blocks=1, 
            launcher=MpiExecLauncher(debug=True), 
            max_blocks=4, 
            min_blocks=0, 
            nodes_per_block=1, 
            parallelism=1, 
            queue='preemptable', 
            scheduler_options='#PBS -l filesystems=home:grand:eagle\n#PBS -N enformer_predict_regions_reference\n#PBS -k doe', 
            select_options='ngpus=4', 
            walltime='00:30:00', 
            worker_init='conda activate /lus/grand/projects/TFXcan/imlab/shared/software/conda_envs/enformer-predict-tools; which python; export LD_LIBRARY_PATH=$LD_LIBRARY_PATH:/lus/grand/projects/TFXcan/imlab/shared/software/conda_envs/enformer-predict-tools/lib'
        ), 
        storage_access=None, 
        worker_debug=False, 
        worker_logdir_root=None, 
        worker_port_range=(54000, 55000), 
        worker_ports=None, 
        working_dir=None
    )], 
    garbage_collect=True, 
    initialize_logging=True, 
    internal_tasks_max_threads=10, 
    max_idletime=120.0, 
    monitoring=None, 
    retries=6, 
    retry_handler=None, 
    run_dir='/lus/grand/projects/covid-ct/imlab/users/shared/enformer_pipeline/enformer_test/predictions_folder/enformer_minimal_some_regions/predictions_2023-04-19/runinfo', 
    strategy='simple', 
    usage_tracking=False
)
1681927195.481294 2023-04-19 17:59:55 MainProcess-136941 MainThread-140030062446400 parsl.dataflow.dflow:88 __init__ INFO: Parsl version: 1.3.0dev0
1681927195.482694 2023-04-19 17:59:55 MainProcess-136941 MainThread-140030062446400 parsl.dataflow.usage_tracking.usage:129 __init__ DEBUG: Tracking status: False
1681927195.483970 2023-04-19 17:59:55 MainProcess-136941 MainThread-140030062446400 parsl.dataflow.dflow:114 __init__ INFO: Run id is: 0c72b750-2dbf-4fd7-91fd-fcd4d22b9de8
1681927195.639127 2023-04-19 17:59:55 MainProcess-136941 MainThread-140030062446400 parsl.dataflow.dflow:121 __init__ DEBUG: Considering candidate for workflow name: /lus/grand/projects/TFXcan/imlab/shared/software/conda_envs/enformer-predict-tools/lib/python3.10/site-packages/parsl/dataflow/dflow.py
1681927195.640554 2023-04-19 17:59:55 MainProcess-136941 MainThread-140030062446400 parsl.dataflow.dflow:121 __init__ DEBUG: Considering candidate for workflow name: /lus/grand/projects/TFXcan/imlab/shared/software/conda_envs/enformer-predict-tools/lib/python3.10/site-packages/parsl/dataflow/dflow.py
1681927195.641634 2023-04-19 17:59:55 MainProcess-136941 MainThread-140030062446400 parsl.dataflow.dflow:121 __init__ DEBUG: Considering candidate for workflow name: /lus/grand/projects/TFXcan/imlab/shared/software/conda_envs/enformer-predict-tools/lib/python3.10/site-packages/typeguard/__init__.py
1681927195.642593 2023-04-19 17:59:55 MainProcess-136941 MainThread-140030062446400 parsl.dataflow.dflow:121 __init__ DEBUG: Considering candidate for workflow name: /lus/grand/projects/covid-ct/imlab/users/shared/enformer_pipeline/parallel_enformer/batch_utils/directives.py
1681927195.643504 2023-04-19 17:59:55 MainProcess-136941 MainThread-140030062446400 parsl.dataflow.dflow:127 __init__ DEBUG: Using directives.py as workflow name
1681927195.644623 2023-04-19 17:59:55 MainProcess-136941 MainThread-140030062446400 parsl.dataflow.memoization:173 __init__ INFO: App caching initialized
1681927195.645651 2023-04-19 17:59:55 MainProcess-136941 MainThread-140030062446400 parsl.dataflow.strategy:127 __init__ DEBUG: Scaling strategy: simple
1681927195.651451 2023-04-19 17:59:55 MainProcess-136941 MainThread-140030062446400 parsl.executors.high_throughput.executor:495 _start_queue_management_thread DEBUG: Starting queue management thread
1681927195.653198 2023-04-19 17:59:55 MainProcess-136941 HTEX-Queue-Management-Thread-140005867517696 parsl.executors.high_throughput.executor:379 _queue_management_worker DEBUG: [MTHREAD] queue management worker starting
1681927195.653387 2023-04-19 17:59:55 MainProcess-136941 MainThread-140030062446400 parsl.executors.high_throughput.executor:499 _start_queue_management_thread DEBUG: Started queue management thread
1681927195.690804 2023-04-19 17:59:55 MainProcess-136941 MainThread-140030062446400 parsl.executors.high_throughput.executor:340 start DEBUG: Created management thread: <Thread(HTEX-Queue-Management-Thread, started daemon 140005867517696)>
1681927195.693435 2023-04-19 17:59:55 MainProcess-136941 MainThread-140030062446400 parsl.executors.high_throughput.executor:312 initialize_scaling DEBUG: Launch command: process_worker_pool.py  --max_workers=4 -a polaris-login-01 -p 0 -c 1.0 -m None --poll 10 --task_port=54135 --result_port=54245 --logdir=/lus/grand/projects/covid-ct/imlab/users/shared/enformer_pipeline/enformer_test/predictions_folder/enformer_minimal_some_regions/predictions_2023-04-19/runinfo/000/htex_PBS --block_id={block_id} --hb_period=30  --hb_threshold=120 --cpu-affinity alternating --available-accelerators 0 1 2 3
1681927195.694591 2023-04-19 17:59:55 MainProcess-136941 MainThread-140030062446400 parsl.executors.high_throughput.executor:315 initialize_scaling DEBUG: Starting HighThroughputExecutor with provider:
PBSProProvider(
    account='TFXcan', 
    channel=LocalChannel(
        envs={}, 
        script_dir='/lus/grand/projects/covid-ct/imlab/users/shared/enformer_pipeline/enformer_test/predictions_folder/enformer_minimal_some_regions/predictions_2023-04-19/runinfo/000/submit_scripts', 
        userhome='/lus/grand/projects/covid-ct/imlab/users/shared/enformer_pipeline'
    ), 
    cmd_timeout=120, 
    cpus_per_node=64, 
    init_blocks=1, 
    launcher=MpiExecLauncher(debug=True), 
    max_blocks=4, 
    min_blocks=0, 
    nodes_per_block=1, 
    parallelism=1, 
    queue='preemptable', 
    scheduler_options='#PBS -l filesystems=home:grand:eagle\n#PBS -N enformer_predict_regions_reference\n#PBS -k doe', 
    select_options='ngpus=4', 
    walltime='00:30:00', 
    worker_init='conda activate /lus/grand/projects/TFXcan/imlab/shared/software/conda_envs/enformer-predict-tools; which python; export LD_LIBRARY_PATH=$LD_LIBRARY_PATH:/lus/grand/projects/TFXcan/imlab/shared/software/conda_envs/enformer-predict-tools/lib'
)
1681927195.697393 2023-04-19 17:59:55 MainProcess-136941 MainThread-140030062446400 parsl.executors.status_handling:162 scale_out INFO: Scaling out by 1 blocks
1681927195.698451 2023-04-19 17:59:55 MainProcess-136941 MainThread-140030062446400 parsl.executors.status_handling:165 scale_out INFO: Allocated block ID 0
1681927195.699618 2023-04-19 17:59:55 MainProcess-136941 MainThread-140030062446400 parsl.providers.pbspro.pbspro:114 submit DEBUG: Requesting 1 nodes_per_block, 1 tasks_per_node
1681927195.700750 2023-04-19 17:59:55 MainProcess-136941 MainThread-140030062446400 parsl.providers.pbspro.pbspro:138 submit DEBUG: Writing submit script
1681927196.004149 2023-04-19 17:59:56 MainProcess-136941 MainThread-140030062446400 parsl.executors.status_handling:180 _launch_block DEBUG: Launched block 0 on executor htex_PBS with job ID 483408.polaris-pbs-01.hsn.cm.polaris.alcf.anl.gov
1681927196.033923 2023-04-19 17:59:56 MainProcess-136941 MainThread-140030062446400 parsl.dataflow.task_status_poller:122 add_executors DEBUG: Adding executor htex_PBS
1681927196.078766 2023-04-19 17:59:56 MainProcess-136941 MainThread-140030062446400 parsl.dataflow.dflow:841 submit DEBUG: Task 0 will be sent to executor htex_PBS
1681927196.082232 2023-04-19 17:59:56 MainProcess-136941 MainThread-140030062446400 parsl.dataflow.dflow:667 _add_output_deps DEBUG: Adding output dependencies
1681927196.083379 2023-04-19 17:59:56 MainProcess-136941 MainThread-140030062446400 parsl.dataflow.dflow:920 submit INFO: Task 0 submitted for App run_batch_predictions, not waiting on any dependency
1681927196.084447 2023-04-19 17:59:56 MainProcess-136941 MainThread-140030062446400 parsl.dataflow.dflow:928 submit DEBUG: Task 0 set to pending state with AppFuture: <AppFuture at 0x7f5641a67880 state=pending>
1681927196.085768 2023-04-19 17:59:56 MainProcess-136941 MainThread-140030062446400 parsl.dataflow.memoization:236 check_memo DEBUG: Task 0 will not be memoized
1681927196.086828 2023-04-19 17:59:56 MainProcess-136941 MainThread-140030062446400 parsl.executors.high_throughput.executor:584 submit DEBUG: Pushing function <function run_batch_predictions at 0x7f5641a336d0> to queue with args ()
1681927196.097440 2023-04-19 17:59:56 MainProcess-136941 MainThread-140030062446400 parsl.dataflow.dflow:628 launch_task INFO: Parsl task 0 try 0 launched on executor htex_PBS with executor id 1
1681927196.098733 2023-04-19 17:59:56 MainProcess-136941 MainThread-140030062446400 parsl.dataflow.dflow:841 submit DEBUG: Task 1 will be sent to executor htex_PBS
1681927196.100609 2023-04-19 17:59:56 MainProcess-136941 MainThread-140030062446400 parsl.dataflow.dflow:667 _add_output_deps DEBUG: Adding output dependencies
1681927196.101697 2023-04-19 17:59:56 MainProcess-136941 MainThread-140030062446400 parsl.dataflow.dflow:920 submit INFO: Task 1 submitted for App run_batch_predictions, not waiting on any dependency
1681927196.102651 2023-04-19 17:59:56 MainProcess-136941 MainThread-140030062446400 parsl.dataflow.dflow:928 submit DEBUG: Task 1 set to pending state with AppFuture: <AppFuture at 0x7f5641a66440 state=pending>
1681927196.103570 2023-04-19 17:59:56 MainProcess-136941 MainThread-140030062446400 parsl.dataflow.memoization:236 check_memo DEBUG: Task 1 will not be memoized
1681927196.105166 2023-04-19 17:59:56 MainProcess-136941 MainThread-140030062446400 parsl.executors.high_throughput.executor:584 submit DEBUG: Pushing function <function run_batch_predictions at 0x7f5641a336d0> to queue with args ()
1681927196.106179 2023-04-19 17:59:56 MainProcess-136941 MainThread-140030062446400 parsl.dataflow.dflow:628 launch_task INFO: Parsl task 1 try 0 launched on executor htex_PBS with executor id 2
1681927196.685889 2023-04-19 17:59:56 MainProcess-136941 FlowControl-Thread-140008444544768 parsl.dataflow.flow_control:105 make_callback ERROR: Flow control callback threw an exception - logging and proceeding anyway
Traceback (most recent call last):
  File "/lus/grand/projects/TFXcan/imlab/shared/software/conda_envs/enformer-predict-tools/lib/python3.10/site-packages/parsl/dataflow/flow_control.py", line 103, in make_callback
    self.callback(tasks=self._event_buffer)
  File "/lus/grand/projects/TFXcan/imlab/shared/software/conda_envs/enformer-predict-tools/lib/python3.10/site-packages/parsl/dataflow/task_status_poller.py", line 110, in poll
    self._update_state()
  File "/lus/grand/projects/TFXcan/imlab/shared/software/conda_envs/enformer-predict-tools/lib/python3.10/site-packages/parsl/dataflow/task_status_poller.py", line 117, in _update_state
    item.poll(now)
  File "/lus/grand/projects/TFXcan/imlab/shared/software/conda_envs/enformer-predict-tools/lib/python3.10/site-packages/parsl/dataflow/task_status_poller.py", line 45, in poll
    self._status = self._executor.status()
  File "/lus/grand/projects/TFXcan/imlab/shared/software/conda_envs/enformer-predict-tools/lib/python3.10/site-packages/parsl/executors/status_handling.py", line 103, in status
    status = self._make_status_dict(block_ids, self._provider.status(job_ids))
  File "/lus/grand/projects/TFXcan/imlab/shared/software/conda_envs/enformer-predict-tools/lib/python3.10/site-packages/parsl/providers/cluster_provider.py", line 142, in status
    self._status()
  File "/lus/grand/projects/TFXcan/imlab/shared/software/conda_envs/enformer-predict-tools/lib/python3.10/site-packages/parsl/providers/torque/torque.py", line 132, in _status
    self.resources[job_id]['status'] = JobStatus(state)
KeyError: '483408.polaris-p*'
1681927201.692284 2023-04-19 18:00:01 MainProcess-136941 FlowControl-Thread-140008444544768 parsl.dataflow.flow_control:105 make_callback ERROR: Flow control callback threw an exception - logging and proceeding anyway
Traceback (most recent call last):
  File "/lus/grand/projects/TFXcan/imlab/shared/software/conda_envs/enformer-predict-tools/lib/python3.10/site-packages/parsl/dataflow/flow_control.py", line 103, in make_callback
    self.callback(tasks=self._event_buffer)
  File "/lus/grand/projects/TFXcan/imlab/shared/software/conda_envs/enformer-predict-tools/lib/python3.10/site-packages/parsl/dataflow/task_status_poller.py", line 110, in poll
    self._update_state()
  File "/lus/grand/projects/TFXcan/imlab/shared/software/conda_envs/enformer-predict-tools/lib/python3.10/site-packages/parsl/dataflow/task_status_poller.py", line 117, in _update_state
    item.poll(now)
  File "/lus/grand/projects/TFXcan/imlab/shared/software/conda_envs/enformer-predict-tools/lib/python3.10/site-packages/parsl/dataflow/task_status_poller.py", line 45, in poll
    self._status = self._executor.status()
  File "/lus/grand/projects/TFXcan/imlab/shared/software/conda_envs/enformer-predict-tools/lib/python3.10/site-packages/parsl/executors/status_handling.py", line 103, in status
    status = self._make_status_dict(block_ids, self._provider.status(job_ids))
  File "/lus/grand/projects/TFXcan/imlab/shared/software/conda_envs/enformer-predict-tools/lib/python3.10/site-packages/parsl/providers/cluster_provider.py", line 142, in status
    self._status()
  File "/lus/grand/projects/TFXcan/imlab/shared/software/conda_envs/enformer-predict-tools/lib/python3.10/site-packages/parsl/providers/torque/torque.py", line 132, in _status
    self.resources[job_id]['status'] = JobStatus(state)
KeyError: '483408.polaris-p*'
1681927206.693226 2023-04-19 18:00:06 MainProcess-136941 FlowControl-Thread-140008444544768 parsl.dataflow.flow_control:105 make_callback ERROR: Flow control callback threw an exception - logging and proceeding anyway
Traceback (most recent call last):
  File "/lus/grand/projects/TFXcan/imlab/shared/software/conda_envs/enformer-predict-tools/lib/python3.10/site-packages/parsl/dataflow/flow_control.py", line 103, in make_callback
    self.callback(tasks=self._event_buffer)
  File "/lus/grand/projects/TFXcan/imlab/shared/software/conda_envs/enformer-predict-tools/lib/python3.10/site-packages/parsl/dataflow/task_status_poller.py", line 110, in poll
    self._update_state()
  File "/lus/grand/projects/TFXcan/imlab/shared/software/conda_envs/enformer-predict-tools/lib/python3.10/site-packages/parsl/dataflow/task_status_poller.py", line 117, in _update_state
    item.poll(now)
  File "/lus/grand/projects/TFXcan/imlab/shared/software/conda_envs/enformer-predict-tools/lib/python3.10/site-packages/parsl/dataflow/task_status_poller.py", line 45, in poll
    self._status = self._executor.status()
  File "/lus/grand/projects/TFXcan/imlab/shared/software/conda_envs/enformer-predict-tools/lib/python3.10/site-packages/parsl/executors/status_handling.py", line 103, in status
    status = self._make_status_dict(block_ids, self._provider.status(job_ids))
  File "/lus/grand/projects/TFXcan/imlab/shared/software/conda_envs/enformer-predict-tools/lib/python3.10/site-packages/parsl/providers/cluster_provider.py", line 142, in status
    self._status()
  File "/lus/grand/projects/TFXcan/imlab/shared/software/conda_envs/enformer-predict-tools/lib/python3.10/site-packages/parsl/providers/torque/torque.py", line 132, in _status
    self.resources[job_id]['status'] = JobStatus(state)
KeyError: '483408.polaris-p*'
1681927211.892281 2023-04-19 18:00:11 MainProcess-136941 FlowControl-Thread-140008444544768 parsl.dataflow.flow_control:105 make_callback ERROR: Flow control callback threw an exception - logging and proceeding anyway
Traceback (most recent call last):
  File "/lus/grand/projects/TFXcan/imlab/shared/software/conda_envs/enformer-predict-tools/lib/python3.10/site-packages/parsl/dataflow/flow_control.py", line 103, in make_callback
    self.callback(tasks=self._event_buffer)
  File "/lus/grand/projects/TFXcan/imlab/shared/software/conda_envs/enformer-predict-tools/lib/python3.10/site-packages/parsl/dataflow/task_status_poller.py", line 110, in poll
    self._update_state()
  File "/lus/grand/projects/TFXcan/imlab/shared/software/conda_envs/enformer-predict-tools/lib/python3.10/site-packages/parsl/dataflow/task_status_poller.py", line 117, in _update_state
    item.poll(now)
  File "/lus/grand/projects/TFXcan/imlab/shared/software/conda_envs/enformer-predict-tools/lib/python3.10/site-packages/parsl/dataflow/task_status_poller.py", line 45, in poll
    self._status = self._executor.status()
  File "/lus/grand/projects/TFXcan/imlab/shared/software/conda_envs/enformer-predict-tools/lib/python3.10/site-packages/parsl/executors/status_handling.py", line 103, in status
    status = self._make_status_dict(block_ids, self._provider.status(job_ids))
  File "/lus/grand/projects/TFXcan/imlab/shared/software/conda_envs/enformer-predict-tools/lib/python3.10/site-packages/parsl/providers/cluster_provider.py", line 142, in status
    self._status()
  File "/lus/grand/projects/TFXcan/imlab/shared/software/conda_envs/enformer-predict-tools/lib/python3.10/site-packages/parsl/providers/torque/torque.py", line 132, in _status
    self.resources[job_id]['status'] = JobStatus(state)
KeyError: '483408.polaris-p*'
1681927216.690005 2023-04-19 18:00:16 MainProcess-136941 FlowControl-Thread-140008444544768 parsl.dataflow.flow_control:105 make_callback ERROR: Flow control callback threw an exception - logging and proceeding anyway
Traceback (most recent call last):
  File "/lus/grand/projects/TFXcan/imlab/shared/software/conda_envs/enformer-predict-tools/lib/python3.10/site-packages/parsl/dataflow/flow_control.py", line 103, in make_callback
    self.callback(tasks=self._event_buffer)
  File "/lus/grand/projects/TFXcan/imlab/shared/software/conda_envs/enformer-predict-tools/lib/python3.10/site-packages/parsl/dataflow/task_status_poller.py", line 110, in poll
    self._update_state()
  File "/lus/grand/projects/TFXcan/imlab/shared/software/conda_envs/enformer-predict-tools/lib/python3.10/site-packages/parsl/dataflow/task_status_poller.py", line 117, in _update_state
    item.poll(now)
  File "/lus/grand/projects/TFXcan/imlab/shared/software/conda_envs/enformer-predict-tools/lib/python3.10/site-packages/parsl/dataflow/task_status_poller.py", line 45, in poll
    self._status = self._executor.status()
  File "/lus/grand/projects/TFXcan/imlab/shared/software/conda_envs/enformer-predict-tools/lib/python3.10/site-packages/parsl/executors/status_handling.py", line 103, in status
    status = self._make_status_dict(block_ids, self._provider.status(job_ids))
  File "/lus/grand/projects/TFXcan/imlab/shared/software/conda_envs/enformer-predict-tools/lib/python3.10/site-packages/parsl/providers/cluster_provider.py", line 142, in status
    self._status()
  File "/lus/grand/projects/TFXcan/imlab/shared/software/conda_envs/enformer-predict-tools/lib/python3.10/site-packages/parsl/providers/torque/torque.py", line 132, in _status
    self.resources[job_id]['status'] = JobStatus(state)
KeyError: '483408.polaris-p*'
1681927221.688826 2023-04-19 18:00:21 MainProcess-136941 FlowControl-Thread-140008444544768 parsl.dataflow.flow_control:105 make_callback ERROR: Flow control callback threw an exception - logging and proceeding anyway
Traceback (most recent call last):
  File "/lus/grand/projects/TFXcan/imlab/shared/software/conda_envs/enformer-predict-tools/lib/python3.10/site-packages/parsl/dataflow/flow_control.py", line 103, in make_callback
    self.callback(tasks=self._event_buffer)
  File "/lus/grand/projects/TFXcan/imlab/shared/software/conda_envs/enformer-predict-tools/lib/python3.10/site-packages/parsl/dataflow/task_status_poller.py", line 110, in poll
    self._update_state()
  File "/lus/grand/projects/TFXcan/imlab/shared/software/conda_envs/enformer-predict-tools/lib/python3.10/site-packages/parsl/dataflow/task_status_poller.py", line 117, in _update_state
    item.poll(now)
  File "/lus/grand/projects/TFXcan/imlab/shared/software/conda_envs/enformer-predict-tools/lib/python3.10/site-packages/parsl/dataflow/task_status_poller.py", line 45, in poll
    self._status = self._executor.status()
  File "/lus/grand/projects/TFXcan/imlab/shared/software/conda_envs/enformer-predict-tools/lib/python3.10/site-packages/parsl/executors/status_handling.py", line 103, in status
    status = self._make_status_dict(block_ids, self._provider.status(job_ids))
  File "/lus/grand/projects/TFXcan/imlab/shared/software/conda_envs/enformer-predict-tools/lib/python3.10/site-packages/parsl/providers/cluster_provider.py", line 142, in status
    self._status()
  File "/lus/grand/projects/TFXcan/imlab/shared/software/conda_envs/enformer-predict-tools/lib/python3.10/site-packages/parsl/providers/torque/torque.py", line 132, in _status
    self.resources[job_id]['status'] = JobStatus(state)
KeyError: '483408.polaris-p*'
1681927226.702958 2023-04-19 18:00:26 MainProcess-136941 FlowControl-Thread-140008444544768 parsl.dataflow.flow_control:105 make_callback ERROR: Flow control callback threw an exception - logging and proceeding anyway
Traceback (most recent call last):
  File "/lus/grand/projects/TFXcan/imlab/shared/software/conda_envs/enformer-predict-tools/lib/python3.10/site-packages/parsl/dataflow/flow_control.py", line 103, in make_callback
    self.callback(tasks=self._event_buffer)
  File "/lus/grand/projects/TFXcan/imlab/shared/software/conda_envs/enformer-predict-tools/lib/python3.10/site-packages/parsl/dataflow/task_status_poller.py", line 110, in poll
    self._update_state()
  File "/lus/grand/projects/TFXcan/imlab/shared/software/conda_envs/enformer-predict-tools/lib/python3.10/site-packages/parsl/dataflow/task_status_poller.py", line 117, in _update_state
    item.poll(now)
  File "/lus/grand/projects/TFXcan/imlab/shared/software/conda_envs/enformer-predict-tools/lib/python3.10/site-packages/parsl/dataflow/task_status_poller.py", line 45, in poll
    self._status = self._executor.status()
  File "/lus/grand/projects/TFXcan/imlab/shared/software/conda_envs/enformer-predict-tools/lib/python3.10/site-packages/parsl/executors/status_handling.py", line 103, in status
    status = self._make_status_dict(block_ids, self._provider.status(job_ids))
  File "/lus/grand/projects/TFXcan/imlab/shared/software/conda_envs/enformer-predict-tools/lib/python3.10/site-packages/parsl/providers/cluster_provider.py", line 142, in status
    self._status()
  File "/lus/grand/projects/TFXcan/imlab/shared/software/conda_envs/enformer-predict-tools/lib/python3.10/site-packages/parsl/providers/torque/torque.py", line 132, in _status
    self.resources[job_id]['status'] = JobStatus(state)
KeyError: '483408.polaris-p*'
1681927231.691037 2023-04-19 18:00:31 MainProcess-136941 FlowControl-Thread-140008444544768 parsl.dataflow.flow_control:105 make_callback ERROR: Flow control callback threw an exception - logging and proceeding anyway
Traceback (most recent call last):
  File "/lus/grand/projects/TFXcan/imlab/shared/software/conda_envs/enformer-predict-tools/lib/python3.10/site-packages/parsl/dataflow/flow_control.py", line 103, in make_callback
    self.callback(tasks=self._event_buffer)
  File "/lus/grand/projects/TFXcan/imlab/shared/software/conda_envs/enformer-predict-tools/lib/python3.10/site-packages/parsl/dataflow/task_status_poller.py", line 110, in poll
    self._update_state()
  File "/lus/grand/projects/TFXcan/imlab/shared/software/conda_envs/enformer-predict-tools/lib/python3.10/site-packages/parsl/dataflow/task_status_poller.py", line 117, in _update_state
    item.poll(now)
  File "/lus/grand/projects/TFXcan/imlab/shared/software/conda_envs/enformer-predict-tools/lib/python3.10/site-packages/parsl/dataflow/task_status_poller.py", line 45, in poll
    self._status = self._executor.status()
  File "/lus/grand/projects/TFXcan/imlab/shared/software/conda_envs/enformer-predict-tools/lib/python3.10/site-packages/parsl/executors/status_handling.py", line 103, in status
    status = self._make_status_dict(block_ids, self._provider.status(job_ids))
  File "/lus/grand/projects/TFXcan/imlab/shared/software/conda_envs/enformer-predict-tools/lib/python3.10/site-packages/parsl/providers/cluster_provider.py", line 142, in status
    self._status()
  File "/lus/grand/projects/TFXcan/imlab/shared/software/conda_envs/enformer-predict-tools/lib/python3.10/site-packages/parsl/providers/torque/torque.py", line 132, in _status
    self.resources[job_id]['status'] = JobStatus(state)
KeyError: '483408.polaris-p*'
1681927236.698693 2023-04-19 18:00:36 MainProcess-136941 FlowControl-Thread-140008444544768 parsl.dataflow.flow_control:105 make_callback ERROR: Flow control callback threw an exception - logging and proceeding anyway
Traceback (most recent call last):
  File "/lus/grand/projects/TFXcan/imlab/shared/software/conda_envs/enformer-predict-tools/lib/python3.10/site-packages/parsl/dataflow/flow_control.py", line 103, in make_callback
    self.callback(tasks=self._event_buffer)
  File "/lus/grand/projects/TFXcan/imlab/shared/software/conda_envs/enformer-predict-tools/lib/python3.10/site-packages/parsl/dataflow/task_status_poller.py", line 110, in poll
    self._update_state()
  File "/lus/grand/projects/TFXcan/imlab/shared/software/conda_envs/enformer-predict-tools/lib/python3.10/site-packages/parsl/dataflow/task_status_poller.py", line 117, in _update_state
    item.poll(now)
  File "/lus/grand/projects/TFXcan/imlab/shared/software/conda_envs/enformer-predict-tools/lib/python3.10/site-packages/parsl/dataflow/task_status_poller.py", line 45, in poll
    self._status = self._executor.status()
  File "/lus/grand/projects/TFXcan/imlab/shared/software/conda_envs/enformer-predict-tools/lib/python3.10/site-packages/parsl/executors/status_handling.py", line 103, in status
    status = self._make_status_dict(block_ids, self._provider.status(job_ids))
  File "/lus/grand/projects/TFXcan/imlab/shared/software/conda_envs/enformer-predict-tools/lib/python3.10/site-packages/parsl/providers/cluster_provider.py", line 142, in status
    self._status()
  File "/lus/grand/projects/TFXcan/imlab/shared/software/conda_envs/enformer-predict-tools/lib/python3.10/site-packages/parsl/providers/torque/torque.py", line 132, in _status
    self.resources[job_id]['status'] = JobStatus(state)
KeyError: '483408.polaris-p*'
1681927241.689903 2023-04-19 18:00:41 MainProcess-136941 FlowControl-Thread-140008444544768 parsl.dataflow.flow_control:105 make_callback ERROR: Flow control callback threw an exception - logging and proceeding anyway
Traceback (most recent call last):
  File "/lus/grand/projects/TFXcan/imlab/shared/software/conda_envs/enformer-predict-tools/lib/python3.10/site-packages/parsl/dataflow/flow_control.py", line 103, in make_callback
    self.callback(tasks=self._event_buffer)
  File "/lus/grand/projects/TFXcan/imlab/shared/software/conda_envs/enformer-predict-tools/lib/python3.10/site-packages/parsl/dataflow/task_status_poller.py", line 110, in poll
    self._update_state()
  File "/lus/grand/projects/TFXcan/imlab/shared/software/conda_envs/enformer-predict-tools/lib/python3.10/site-packages/parsl/dataflow/task_status_poller.py", line 117, in _update_state
    item.poll(now)
  File "/lus/grand/projects/TFXcan/imlab/shared/software/conda_envs/enformer-predict-tools/lib/python3.10/site-packages/parsl/dataflow/task_status_poller.py", line 45, in poll
    self._status = self._executor.status()
  File "/lus/grand/projects/TFXcan/imlab/shared/software/conda_envs/enformer-predict-tools/lib/python3.10/site-packages/parsl/executors/status_handling.py", line 103, in status
    status = self._make_status_dict(block_ids, self._provider.status(job_ids))
  File "/lus/grand/projects/TFXcan/imlab/shared/software/conda_envs/enformer-predict-tools/lib/python3.10/site-packages/parsl/providers/cluster_provider.py", line 142, in status
    self._status()
  File "/lus/grand/projects/TFXcan/imlab/shared/software/conda_envs/enformer-predict-tools/lib/python3.10/site-packages/parsl/providers/torque/torque.py", line 132, in _status
    self.resources[job_id]['status'] = JobStatus(state)
KeyError: '483408.polaris-p*'
1681927246.690526 2023-04-19 18:00:46 MainProcess-136941 FlowControl-Thread-140008444544768 parsl.dataflow.flow_control:105 make_callback ERROR: Flow control callback threw an exception - logging and proceeding anyway
Traceback (most recent call last):
  File "/lus/grand/projects/TFXcan/imlab/shared/software/conda_envs/enformer-predict-tools/lib/python3.10/site-packages/parsl/dataflow/flow_control.py", line 103, in make_callback
    self.callback(tasks=self._event_buffer)
  File "/lus/grand/projects/TFXcan/imlab/shared/software/conda_envs/enformer-predict-tools/lib/python3.10/site-packages/parsl/dataflow/task_status_poller.py", line 110, in poll
    self._update_state()
  File "/lus/grand/projects/TFXcan/imlab/shared/software/conda_envs/enformer-predict-tools/lib/python3.10/site-packages/parsl/dataflow/task_status_poller.py", line 117, in _update_state
    item.poll(now)
  File "/lus/grand/projects/TFXcan/imlab/shared/software/conda_envs/enformer-predict-tools/lib/python3.10/site-packages/parsl/dataflow/task_status_poller.py", line 45, in poll
    self._status = self._executor.status()
  File "/lus/grand/projects/TFXcan/imlab/shared/software/conda_envs/enformer-predict-tools/lib/python3.10/site-packages/parsl/executors/status_handling.py", line 103, in status
    status = self._make_status_dict(block_ids, self._provider.status(job_ids))
  File "/lus/grand/projects/TFXcan/imlab/shared/software/conda_envs/enformer-predict-tools/lib/python3.10/site-packages/parsl/providers/cluster_provider.py", line 142, in status
    self._status()
  File "/lus/grand/projects/TFXcan/imlab/shared/software/conda_envs/enformer-predict-tools/lib/python3.10/site-packages/parsl/providers/torque/torque.py", line 132, in _status
    self.resources[job_id]['status'] = JobStatus(state)
KeyError: '483408.polaris-p*'
1681927251.714035 2023-04-19 18:00:51 MainProcess-136941 FlowControl-Thread-140008444544768 parsl.dataflow.flow_control:105 make_callback ERROR: Flow control callback threw an exception - logging and proceeding anyway
Traceback (most recent call last):
  File "/lus/grand/projects/TFXcan/imlab/shared/software/conda_envs/enformer-predict-tools/lib/python3.10/site-packages/parsl/dataflow/flow_control.py", line 103, in make_callback
    self.callback(tasks=self._event_buffer)
  File "/lus/grand/projects/TFXcan/imlab/shared/software/conda_envs/enformer-predict-tools/lib/python3.10/site-packages/parsl/dataflow/task_status_poller.py", line 110, in poll
    self._update_state()
  File "/lus/grand/projects/TFXcan/imlab/shared/software/conda_envs/enformer-predict-tools/lib/python3.10/site-packages/parsl/dataflow/task_status_poller.py", line 117, in _update_state
    item.poll(now)
  File "/lus/grand/projects/TFXcan/imlab/shared/software/conda_envs/enformer-predict-tools/lib/python3.10/site-packages/parsl/dataflow/task_status_poller.py", line 45, in poll
    self._status = self._executor.status()
  File "/lus/grand/projects/TFXcan/imlab/shared/software/conda_envs/enformer-predict-tools/lib/python3.10/site-packages/parsl/executors/status_handling.py", line 103, in status
    status = self._make_status_dict(block_ids, self._provider.status(job_ids))
  File "/lus/grand/projects/TFXcan/imlab/shared/software/conda_envs/enformer-predict-tools/lib/python3.10/site-packages/parsl/providers/cluster_provider.py", line 142, in status
    self._status()
  File "/lus/grand/projects/TFXcan/imlab/shared/software/conda_envs/enformer-predict-tools/lib/python3.10/site-packages/parsl/providers/torque/torque.py", line 132, in _status
    self.resources[job_id]['status'] = JobStatus(state)
KeyError: '483408.polaris-p*'
1681927256.816444 2023-04-19 18:00:56 MainProcess-136941 FlowControl-Thread-140008444544768 parsl.dataflow.flow_control:105 make_callback ERROR: Flow control callback threw an exception - logging and proceeding anyway
Traceback (most recent call last):
  File "/lus/grand/projects/TFXcan/imlab/shared/software/conda_envs/enformer-predict-tools/lib/python3.10/site-packages/parsl/dataflow/flow_control.py", line 103, in make_callback
    self.callback(tasks=self._event_buffer)
  File "/lus/grand/projects/TFXcan/imlab/shared/software/conda_envs/enformer-predict-tools/lib/python3.10/site-packages/parsl/dataflow/task_status_poller.py", line 110, in poll
    self._update_state()
  File "/lus/grand/projects/TFXcan/imlab/shared/software/conda_envs/enformer-predict-tools/lib/python3.10/site-packages/parsl/dataflow/task_status_poller.py", line 117, in _update_state
    item.poll(now)
  File "/lus/grand/projects/TFXcan/imlab/shared/software/conda_envs/enformer-predict-tools/lib/python3.10/site-packages/parsl/dataflow/task_status_poller.py", line 45, in poll
    self._status = self._executor.status()
  File "/lus/grand/projects/TFXcan/imlab/shared/software/conda_envs/enformer-predict-tools/lib/python3.10/site-packages/parsl/executors/status_handling.py", line 103, in status
    status = self._make_status_dict(block_ids, self._provider.status(job_ids))
  File "/lus/grand/projects/TFXcan/imlab/shared/software/conda_envs/enformer-predict-tools/lib/python3.10/site-packages/parsl/providers/cluster_provider.py", line 142, in status
    self._status()
  File "/lus/grand/projects/TFXcan/imlab/shared/software/conda_envs/enformer-predict-tools/lib/python3.10/site-packages/parsl/providers/torque/torque.py", line 132, in _status
    self.resources[job_id]['status'] = JobStatus(state)
KeyError: '483408.polaris-p*'
1681927261.773941 2023-04-19 18:01:01 MainProcess-136941 FlowControl-Thread-140008444544768 parsl.dataflow.flow_control:105 make_callback ERROR: Flow control callback threw an exception - logging and proceeding anyway
Traceback (most recent call last):
  File "/lus/grand/projects/TFXcan/imlab/shared/software/conda_envs/enformer-predict-tools/lib/python3.10/site-packages/parsl/dataflow/flow_control.py", line 103, in make_callback
    self.callback(tasks=self._event_buffer)
  File "/lus/grand/projects/TFXcan/imlab/shared/software/conda_envs/enformer-predict-tools/lib/python3.10/site-packages/parsl/dataflow/task_status_poller.py", line 110, in poll
    self._update_state()
  File "/lus/grand/projects/TFXcan/imlab/shared/software/conda_envs/enformer-predict-tools/lib/python3.10/site-packages/parsl/dataflow/task_status_poller.py", line 117, in _update_state
    item.poll(now)
  File "/lus/grand/projects/TFXcan/imlab/shared/software/conda_envs/enformer-predict-tools/lib/python3.10/site-packages/parsl/dataflow/task_status_poller.py", line 45, in poll
    self._status = self._executor.status()
  File "/lus/grand/projects/TFXcan/imlab/shared/software/conda_envs/enformer-predict-tools/lib/python3.10/site-packages/parsl/executors/status_handling.py", line 103, in status
    status = self._make_status_dict(block_ids, self._provider.status(job_ids))
  File "/lus/grand/projects/TFXcan/imlab/shared/software/conda_envs/enformer-predict-tools/lib/python3.10/site-packages/parsl/providers/cluster_provider.py", line 142, in status
    self._status()
  File "/lus/grand/projects/TFXcan/imlab/shared/software/conda_envs/enformer-predict-tools/lib/python3.10/site-packages/parsl/providers/torque/torque.py", line 132, in _status
    self.resources[job_id]['status'] = JobStatus(state)
KeyError: '483408.polaris-p*'
1681927266.691689 2023-04-19 18:01:06 MainProcess-136941 FlowControl-Thread-140008444544768 parsl.dataflow.flow_control:105 make_callback ERROR: Flow control callback threw an exception - logging and proceeding anyway
Traceback (most recent call last):
  File "/lus/grand/projects/TFXcan/imlab/shared/software/conda_envs/enformer-predict-tools/lib/python3.10/site-packages/parsl/dataflow/flow_control.py", line 103, in make_callback
    self.callback(tasks=self._event_buffer)
  File "/lus/grand/projects/TFXcan/imlab/shared/software/conda_envs/enformer-predict-tools/lib/python3.10/site-packages/parsl/dataflow/task_status_poller.py", line 110, in poll
    self._update_state()
  File "/lus/grand/projects/TFXcan/imlab/shared/software/conda_envs/enformer-predict-tools/lib/python3.10/site-packages/parsl/dataflow/task_status_poller.py", line 117, in _update_state
    item.poll(now)
  File "/lus/grand/projects/TFXcan/imlab/shared/software/conda_envs/enformer-predict-tools/lib/python3.10/site-packages/parsl/dataflow/task_status_poller.py", line 45, in poll
    self._status = self._executor.status()
  File "/lus/grand/projects/TFXcan/imlab/shared/software/conda_envs/enformer-predict-tools/lib/python3.10/site-packages/parsl/executors/status_handling.py", line 103, in status
    status = self._make_status_dict(block_ids, self._provider.status(job_ids))
  File "/lus/grand/projects/TFXcan/imlab/shared/software/conda_envs/enformer-predict-tools/lib/python3.10/site-packages/parsl/providers/cluster_provider.py", line 142, in status
    self._status()
  File "/lus/grand/projects/TFXcan/imlab/shared/software/conda_envs/enformer-predict-tools/lib/python3.10/site-packages/parsl/providers/torque/torque.py", line 132, in _status
    self.resources[job_id]['status'] = JobStatus(state)
KeyError: '483408.polaris-p*'
1681927271.702775 2023-04-19 18:01:11 MainProcess-136941 FlowControl-Thread-140008444544768 parsl.dataflow.flow_control:105 make_callback ERROR: Flow control callback threw an exception - logging and proceeding anyway
Traceback (most recent call last):
  File "/lus/grand/projects/TFXcan/imlab/shared/software/conda_envs/enformer-predict-tools/lib/python3.10/site-packages/parsl/dataflow/flow_control.py", line 103, in make_callback
    self.callback(tasks=self._event_buffer)
  File "/lus/grand/projects/TFXcan/imlab/shared/software/conda_envs/enformer-predict-tools/lib/python3.10/site-packages/parsl/dataflow/task_status_poller.py", line 110, in poll
    self._update_state()
  File "/lus/grand/projects/TFXcan/imlab/shared/software/conda_envs/enformer-predict-tools/lib/python3.10/site-packages/parsl/dataflow/task_status_poller.py", line 117, in _update_state
    item.poll(now)
  File "/lus/grand/projects/TFXcan/imlab/shared/software/conda_envs/enformer-predict-tools/lib/python3.10/site-packages/parsl/dataflow/task_status_poller.py", line 45, in poll
    self._status = self._executor.status()
  File "/lus/grand/projects/TFXcan/imlab/shared/software/conda_envs/enformer-predict-tools/lib/python3.10/site-packages/parsl/executors/status_handling.py", line 103, in status
    status = self._make_status_dict(block_ids, self._provider.status(job_ids))
  File "/lus/grand/projects/TFXcan/imlab/shared/software/conda_envs/enformer-predict-tools/lib/python3.10/site-packages/parsl/providers/cluster_provider.py", line 142, in status
    self._status()
  File "/lus/grand/projects/TFXcan/imlab/shared/software/conda_envs/enformer-predict-tools/lib/python3.10/site-packages/parsl/providers/torque/torque.py", line 132, in _status
    self.resources[job_id]['status'] = JobStatus(state)
KeyError: '483408.polaris-p*'
1681927276.894847 2023-04-19 18:01:16 MainProcess-136941 FlowControl-Thread-140008444544768 parsl.dataflow.flow_control:105 make_callback ERROR: Flow control callback threw an exception - logging and proceeding anyway
Traceback (most recent call last):
  File "/lus/grand/projects/TFXcan/imlab/shared/software/conda_envs/enformer-predict-tools/lib/python3.10/site-packages/parsl/dataflow/flow_control.py", line 103, in make_callback
    self.callback(tasks=self._event_buffer)
  File "/lus/grand/projects/TFXcan/imlab/shared/software/conda_envs/enformer-predict-tools/lib/python3.10/site-packages/parsl/dataflow/task_status_poller.py", line 110, in poll
    self._update_state()
  File "/lus/grand/projects/TFXcan/imlab/shared/software/conda_envs/enformer-predict-tools/lib/python3.10/site-packages/parsl/dataflow/task_status_poller.py", line 117, in _update_state
    item.poll(now)
  File "/lus/grand/projects/TFXcan/imlab/shared/software/conda_envs/enformer-predict-tools/lib/python3.10/site-packages/parsl/dataflow/task_status_poller.py", line 45, in poll
    self._status = self._executor.status()
  File "/lus/grand/projects/TFXcan/imlab/shared/software/conda_envs/enformer-predict-tools/lib/python3.10/site-packages/parsl/executors/status_handling.py", line 103, in status
    status = self._make_status_dict(block_ids, self._provider.status(job_ids))
  File "/lus/grand/projects/TFXcan/imlab/shared/software/conda_envs/enformer-predict-tools/lib/python3.10/site-packages/parsl/providers/cluster_provider.py", line 142, in status
    self._status()
  File "/lus/grand/projects/TFXcan/imlab/shared/software/conda_envs/enformer-predict-tools/lib/python3.10/site-packages/parsl/providers/torque/torque.py", line 132, in _status
    self.resources[job_id]['status'] = JobStatus(state)
KeyError: '483408.polaris-p*'
1681927281.694138 2023-04-19 18:01:21 MainProcess-136941 FlowControl-Thread-140008444544768 parsl.dataflow.flow_control:105 make_callback ERROR: Flow control callback threw an exception - logging and proceeding anyway
Traceback (most recent call last):
  File "/lus/grand/projects/TFXcan/imlab/shared/software/conda_envs/enformer-predict-tools/lib/python3.10/site-packages/parsl/dataflow/flow_control.py", line 103, in make_callback
    self.callback(tasks=self._event_buffer)
  File "/lus/grand/projects/TFXcan/imlab/shared/software/conda_envs/enformer-predict-tools/lib/python3.10/site-packages/parsl/dataflow/task_status_poller.py", line 110, in poll
    self._update_state()
  File "/lus/grand/projects/TFXcan/imlab/shared/software/conda_envs/enformer-predict-tools/lib/python3.10/site-packages/parsl/dataflow/task_status_poller.py", line 117, in _update_state
    item.poll(now)
  File "/lus/grand/projects/TFXcan/imlab/shared/software/conda_envs/enformer-predict-tools/lib/python3.10/site-packages/parsl/dataflow/task_status_poller.py", line 45, in poll
    self._status = self._executor.status()
  File "/lus/grand/projects/TFXcan/imlab/shared/software/conda_envs/enformer-predict-tools/lib/python3.10/site-packages/parsl/executors/status_handling.py", line 103, in status
    status = self._make_status_dict(block_ids, self._provider.status(job_ids))
  File "/lus/grand/projects/TFXcan/imlab/shared/software/conda_envs/enformer-predict-tools/lib/python3.10/site-packages/parsl/providers/cluster_provider.py", line 142, in status
    self._status()
  File "/lus/grand/projects/TFXcan/imlab/shared/software/conda_envs/enformer-predict-tools/lib/python3.10/site-packages/parsl/providers/torque/torque.py", line 132, in _status
    self.resources[job_id]['status'] = JobStatus(state)
KeyError: '483408.polaris-p*'
1681927286.693204 2023-04-19 18:01:26 MainProcess-136941 FlowControl-Thread-140008444544768 parsl.dataflow.flow_control:105 make_callback ERROR: Flow control callback threw an exception - logging and proceeding anyway
Traceback (most recent call last):
  File "/lus/grand/projects/TFXcan/imlab/shared/software/conda_envs/enformer-predict-tools/lib/python3.10/site-packages/parsl/dataflow/flow_control.py", line 103, in make_callback
    self.callback(tasks=self._event_buffer)
  File "/lus/grand/projects/TFXcan/imlab/shared/software/conda_envs/enformer-predict-tools/lib/python3.10/site-packages/parsl/dataflow/task_status_poller.py", line 110, in poll
    self._update_state()
  File "/lus/grand/projects/TFXcan/imlab/shared/software/conda_envs/enformer-predict-tools/lib/python3.10/site-packages/parsl/dataflow/task_status_poller.py", line 117, in _update_state
    item.poll(now)
  File "/lus/grand/projects/TFXcan/imlab/shared/software/conda_envs/enformer-predict-tools/lib/python3.10/site-packages/parsl/dataflow/task_status_poller.py", line 45, in poll
    self._status = self._executor.status()
  File "/lus/grand/projects/TFXcan/imlab/shared/software/conda_envs/enformer-predict-tools/lib/python3.10/site-packages/parsl/executors/status_handling.py", line 103, in status
    status = self._make_status_dict(block_ids, self._provider.status(job_ids))
  File "/lus/grand/projects/TFXcan/imlab/shared/software/conda_envs/enformer-predict-tools/lib/python3.10/site-packages/parsl/providers/cluster_provider.py", line 142, in status
    self._status()
  File "/lus/grand/projects/TFXcan/imlab/shared/software/conda_envs/enformer-predict-tools/lib/python3.10/site-packages/parsl/providers/torque/torque.py", line 132, in _status
    self.resources[job_id]['status'] = JobStatus(state)
KeyError: '483408.polaris-p*'
1681927291.703634 2023-04-19 18:01:31 MainProcess-136941 FlowControl-Thread-140008444544768 parsl.dataflow.flow_control:105 make_callback ERROR: Flow control callback threw an exception - logging and proceeding anyway
Traceback (most recent call last):
  File "/lus/grand/projects/TFXcan/imlab/shared/software/conda_envs/enformer-predict-tools/lib/python3.10/site-packages/parsl/dataflow/flow_control.py", line 103, in make_callback
    self.callback(tasks=self._event_buffer)
  File "/lus/grand/projects/TFXcan/imlab/shared/software/conda_envs/enformer-predict-tools/lib/python3.10/site-packages/parsl/dataflow/task_status_poller.py", line 110, in poll
    self._update_state()
  File "/lus/grand/projects/TFXcan/imlab/shared/software/conda_envs/enformer-predict-tools/lib/python3.10/site-packages/parsl/dataflow/task_status_poller.py", line 117, in _update_state
    item.poll(now)
  File "/lus/grand/projects/TFXcan/imlab/shared/software/conda_envs/enformer-predict-tools/lib/python3.10/site-packages/parsl/dataflow/task_status_poller.py", line 45, in poll
    self._status = self._executor.status()
  File "/lus/grand/projects/TFXcan/imlab/shared/software/conda_envs/enformer-predict-tools/lib/python3.10/site-packages/parsl/executors/status_handling.py", line 103, in status
    status = self._make_status_dict(block_ids, self._provider.status(job_ids))
  File "/lus/grand/projects/TFXcan/imlab/shared/software/conda_envs/enformer-predict-tools/lib/python3.10/site-packages/parsl/providers/cluster_provider.py", line 142, in status
    self._status()
  File "/lus/grand/projects/TFXcan/imlab/shared/software/conda_envs/enformer-predict-tools/lib/python3.10/site-packages/parsl/providers/torque/torque.py", line 132, in _status
    self.resources[job_id]['status'] = JobStatus(state)
KeyError: '483408.polaris-p*'
1681927296.695858 2023-04-19 18:01:36 MainProcess-136941 FlowControl-Thread-140008444544768 parsl.dataflow.flow_control:105 make_callback ERROR: Flow control callback threw an exception - logging and proceeding anyway
Traceback (most recent call last):
  File "/lus/grand/projects/TFXcan/imlab/shared/software/conda_envs/enformer-predict-tools/lib/python3.10/site-packages/parsl/dataflow/flow_control.py", line 103, in make_callback
    self.callback(tasks=self._event_buffer)
  File "/lus/grand/projects/TFXcan/imlab/shared/software/conda_envs/enformer-predict-tools/lib/python3.10/site-packages/parsl/dataflow/task_status_poller.py", line 110, in poll
    self._update_state()
  File "/lus/grand/projects/TFXcan/imlab/shared/software/conda_envs/enformer-predict-tools/lib/python3.10/site-packages/parsl/dataflow/task_status_poller.py", line 117, in _update_state
    item.poll(now)
  File "/lus/grand/projects/TFXcan/imlab/shared/software/conda_envs/enformer-predict-tools/lib/python3.10/site-packages/parsl/dataflow/task_status_poller.py", line 45, in poll
    self._status = self._executor.status()
  File "/lus/grand/projects/TFXcan/imlab/shared/software/conda_envs/enformer-predict-tools/lib/python3.10/site-packages/parsl/executors/status_handling.py", line 103, in status
    status = self._make_status_dict(block_ids, self._provider.status(job_ids))
  File "/lus/grand/projects/TFXcan/imlab/shared/software/conda_envs/enformer-predict-tools/lib/python3.10/site-packages/parsl/providers/cluster_provider.py", line 142, in status
    self._status()
  File "/lus/grand/projects/TFXcan/imlab/shared/software/conda_envs/enformer-predict-tools/lib/python3.10/site-packages/parsl/providers/torque/torque.py", line 132, in _status
    self.resources[job_id]['status'] = JobStatus(state)
KeyError: '483408.polaris-p*'
1681927301.699414 2023-04-19 18:01:41 MainProcess-136941 FlowControl-Thread-140008444544768 parsl.dataflow.flow_control:105 make_callback ERROR: Flow control callback threw an exception - logging and proceeding anyway
Traceback (most recent call last):
  File "/lus/grand/projects/TFXcan/imlab/shared/software/conda_envs/enformer-predict-tools/lib/python3.10/site-packages/parsl/dataflow/flow_control.py", line 103, in make_callback
    self.callback(tasks=self._event_buffer)
  File "/lus/grand/projects/TFXcan/imlab/shared/software/conda_envs/enformer-predict-tools/lib/python3.10/site-packages/parsl/dataflow/task_status_poller.py", line 110, in poll
    self._update_state()
  File "/lus/grand/projects/TFXcan/imlab/shared/software/conda_envs/enformer-predict-tools/lib/python3.10/site-packages/parsl/dataflow/task_status_poller.py", line 117, in _update_state
    item.poll(now)
  File "/lus/grand/projects/TFXcan/imlab/shared/software/conda_envs/enformer-predict-tools/lib/python3.10/site-packages/parsl/dataflow/task_status_poller.py", line 45, in poll
    self._status = self._executor.status()
  File "/lus/grand/projects/TFXcan/imlab/shared/software/conda_envs/enformer-predict-tools/lib/python3.10/site-packages/parsl/executors/status_handling.py", line 103, in status
    status = self._make_status_dict(block_ids, self._provider.status(job_ids))
  File "/lus/grand/projects/TFXcan/imlab/shared/software/conda_envs/enformer-predict-tools/lib/python3.10/site-packages/parsl/providers/cluster_provider.py", line 142, in status
    self._status()
  File "/lus/grand/projects/TFXcan/imlab/shared/software/conda_envs/enformer-predict-tools/lib/python3.10/site-packages/parsl/providers/torque/torque.py", line 132, in _status
    self.resources[job_id]['status'] = JobStatus(state)
KeyError: '483408.polaris-p*'
1681927306.693943 2023-04-19 18:01:46 MainProcess-136941 FlowControl-Thread-140008444544768 parsl.dataflow.flow_control:105 make_callback ERROR: Flow control callback threw an exception - logging and proceeding anyway
Traceback (most recent call last):
  File "/lus/grand/projects/TFXcan/imlab/shared/software/conda_envs/enformer-predict-tools/lib/python3.10/site-packages/parsl/dataflow/flow_control.py", line 103, in make_callback
    self.callback(tasks=self._event_buffer)
  File "/lus/grand/projects/TFXcan/imlab/shared/software/conda_envs/enformer-predict-tools/lib/python3.10/site-packages/parsl/dataflow/task_status_poller.py", line 110, in poll
    self._update_state()
  File "/lus/grand/projects/TFXcan/imlab/shared/software/conda_envs/enformer-predict-tools/lib/python3.10/site-packages/parsl/dataflow/task_status_poller.py", line 117, in _update_state
    item.poll(now)
  File "/lus/grand/projects/TFXcan/imlab/shared/software/conda_envs/enformer-predict-tools/lib/python3.10/site-packages/parsl/dataflow/task_status_poller.py", line 45, in poll
    self._status = self._executor.status()
  File "/lus/grand/projects/TFXcan/imlab/shared/software/conda_envs/enformer-predict-tools/lib/python3.10/site-packages/parsl/executors/status_handling.py", line 103, in status
    status = self._make_status_dict(block_ids, self._provider.status(job_ids))
  File "/lus/grand/projects/TFXcan/imlab/shared/software/conda_envs/enformer-predict-tools/lib/python3.10/site-packages/parsl/providers/cluster_provider.py", line 142, in status
    self._status()
  File "/lus/grand/projects/TFXcan/imlab/shared/software/conda_envs/enformer-predict-tools/lib/python3.10/site-packages/parsl/providers/torque/torque.py", line 132, in _status
    self.resources[job_id]['status'] = JobStatus(state)
KeyError: '483408.polaris-p*'
1681927311.695355 2023-04-19 18:01:51 MainProcess-136941 FlowControl-Thread-140008444544768 parsl.dataflow.flow_control:105 make_callback ERROR: Flow control callback threw an exception - logging and proceeding anyway
Traceback (most recent call last):
  File "/lus/grand/projects/TFXcan/imlab/shared/software/conda_envs/enformer-predict-tools/lib/python3.10/site-packages/parsl/dataflow/flow_control.py", line 103, in make_callback
    self.callback(tasks=self._event_buffer)
  File "/lus/grand/projects/TFXcan/imlab/shared/software/conda_envs/enformer-predict-tools/lib/python3.10/site-packages/parsl/dataflow/task_status_poller.py", line 110, in poll
    self._update_state()
  File "/lus/grand/projects/TFXcan/imlab/shared/software/conda_envs/enformer-predict-tools/lib/python3.10/site-packages/parsl/dataflow/task_status_poller.py", line 117, in _update_state
    item.poll(now)
  File "/lus/grand/projects/TFXcan/imlab/shared/software/conda_envs/enformer-predict-tools/lib/python3.10/site-packages/parsl/dataflow/task_status_poller.py", line 45, in poll
    self._status = self._executor.status()
  File "/lus/grand/projects/TFXcan/imlab/shared/software/conda_envs/enformer-predict-tools/lib/python3.10/site-packages/parsl/executors/status_handling.py", line 103, in status
    status = self._make_status_dict(block_ids, self._provider.status(job_ids))
  File "/lus/grand/projects/TFXcan/imlab/shared/software/conda_envs/enformer-predict-tools/lib/python3.10/site-packages/parsl/providers/cluster_provider.py", line 142, in status
    self._status()
  File "/lus/grand/projects/TFXcan/imlab/shared/software/conda_envs/enformer-predict-tools/lib/python3.10/site-packages/parsl/providers/torque/torque.py", line 132, in _status
    self.resources[job_id]['status'] = JobStatus(state)
KeyError: '483408.polaris-p*'
1681927316.688941 2023-04-19 18:01:56 MainProcess-136941 FlowControl-Thread-140008444544768 parsl.dataflow.flow_control:105 make_callback ERROR: Flow control callback threw an exception - logging and proceeding anyway
Traceback (most recent call last):
  File "/lus/grand/projects/TFXcan/imlab/shared/software/conda_envs/enformer-predict-tools/lib/python3.10/site-packages/parsl/dataflow/flow_control.py", line 103, in make_callback
    self.callback(tasks=self._event_buffer)
  File "/lus/grand/projects/TFXcan/imlab/shared/software/conda_envs/enformer-predict-tools/lib/python3.10/site-packages/parsl/dataflow/task_status_poller.py", line 110, in poll
    self._update_state()
  File "/lus/grand/projects/TFXcan/imlab/shared/software/conda_envs/enformer-predict-tools/lib/python3.10/site-packages/parsl/dataflow/task_status_poller.py", line 117, in _update_state
    item.poll(now)
  File "/lus/grand/projects/TFXcan/imlab/shared/software/conda_envs/enformer-predict-tools/lib/python3.10/site-packages/parsl/dataflow/task_status_poller.py", line 45, in poll
    self._status = self._executor.status()
  File "/lus/grand/projects/TFXcan/imlab/shared/software/conda_envs/enformer-predict-tools/lib/python3.10/site-packages/parsl/executors/status_handling.py", line 103, in status
    status = self._make_status_dict(block_ids, self._provider.status(job_ids))
  File "/lus/grand/projects/TFXcan/imlab/shared/software/conda_envs/enformer-predict-tools/lib/python3.10/site-packages/parsl/providers/cluster_provider.py", line 142, in status
    self._status()
  File "/lus/grand/projects/TFXcan/imlab/shared/software/conda_envs/enformer-predict-tools/lib/python3.10/site-packages/parsl/providers/torque/torque.py", line 132, in _status
    self.resources[job_id]['status'] = JobStatus(state)
KeyError: '483408.polaris-p*'
1681927321.692060 2023-04-19 18:02:01 MainProcess-136941 FlowControl-Thread-140008444544768 parsl.dataflow.flow_control:105 make_callback ERROR: Flow control callback threw an exception - logging and proceeding anyway
Traceback (most recent call last):
  File "/lus/grand/projects/TFXcan/imlab/shared/software/conda_envs/enformer-predict-tools/lib/python3.10/site-packages/parsl/dataflow/flow_control.py", line 103, in make_callback
    self.callback(tasks=self._event_buffer)
  File "/lus/grand/projects/TFXcan/imlab/shared/software/conda_envs/enformer-predict-tools/lib/python3.10/site-packages/parsl/dataflow/task_status_poller.py", line 110, in poll
    self._update_state()
  File "/lus/grand/projects/TFXcan/imlab/shared/software/conda_envs/enformer-predict-tools/lib/python3.10/site-packages/parsl/dataflow/task_status_poller.py", line 117, in _update_state
    item.poll(now)
  File "/lus/grand/projects/TFXcan/imlab/shared/software/conda_envs/enformer-predict-tools/lib/python3.10/site-packages/parsl/dataflow/task_status_poller.py", line 45, in poll
    self._status = self._executor.status()
  File "/lus/grand/projects/TFXcan/imlab/shared/software/conda_envs/enformer-predict-tools/lib/python3.10/site-packages/parsl/executors/status_handling.py", line 103, in status
    status = self._make_status_dict(block_ids, self._provider.status(job_ids))
  File "/lus/grand/projects/TFXcan/imlab/shared/software/conda_envs/enformer-predict-tools/lib/python3.10/site-packages/parsl/providers/cluster_provider.py", line 142, in status
    self._status()
  File "/lus/grand/projects/TFXcan/imlab/shared/software/conda_envs/enformer-predict-tools/lib/python3.10/site-packages/parsl/providers/torque/torque.py", line 132, in _status
    self.resources[job_id]['status'] = JobStatus(state)
KeyError: '483408.polaris-p*'
1681927326.694026 2023-04-19 18:02:06 MainProcess-136941 FlowControl-Thread-140008444544768 parsl.dataflow.flow_control:105 make_callback ERROR: Flow control callback threw an exception - logging and proceeding anyway
Traceback (most recent call last):
  File "/lus/grand/projects/TFXcan/imlab/shared/software/conda_envs/enformer-predict-tools/lib/python3.10/site-packages/parsl/dataflow/flow_control.py", line 103, in make_callback
    self.callback(tasks=self._event_buffer)
  File "/lus/grand/projects/TFXcan/imlab/shared/software/conda_envs/enformer-predict-tools/lib/python3.10/site-packages/parsl/dataflow/task_status_poller.py", line 110, in poll
    self._update_state()
  File "/lus/grand/projects/TFXcan/imlab/shared/software/conda_envs/enformer-predict-tools/lib/python3.10/site-packages/parsl/dataflow/task_status_poller.py", line 117, in _update_state
    item.poll(now)
  File "/lus/grand/projects/TFXcan/imlab/shared/software/conda_envs/enformer-predict-tools/lib/python3.10/site-packages/parsl/dataflow/task_status_poller.py", line 45, in poll
    self._status = self._executor.status()
  File "/lus/grand/projects/TFXcan/imlab/shared/software/conda_envs/enformer-predict-tools/lib/python3.10/site-packages/parsl/executors/status_handling.py", line 103, in status
    status = self._make_status_dict(block_ids, self._provider.status(job_ids))
  File "/lus/grand/projects/TFXcan/imlab/shared/software/conda_envs/enformer-predict-tools/lib/python3.10/site-packages/parsl/providers/cluster_provider.py", line 142, in status
    self._status()
  File "/lus/grand/projects/TFXcan/imlab/shared/software/conda_envs/enformer-predict-tools/lib/python3.10/site-packages/parsl/providers/torque/torque.py", line 132, in _status
    self.resources[job_id]['status'] = JobStatus(state)
KeyError: '483408.polaris-p*'
1681927331.695543 2023-04-19 18:02:11 MainProcess-136941 FlowControl-Thread-140008444544768 parsl.dataflow.flow_control:105 make_callback ERROR: Flow control callback threw an exception - logging and proceeding anyway
Traceback (most recent call last):
  File "/lus/grand/projects/TFXcan/imlab/shared/software/conda_envs/enformer-predict-tools/lib/python3.10/site-packages/parsl/dataflow/flow_control.py", line 103, in make_callback
    self.callback(tasks=self._event_buffer)
  File "/lus/grand/projects/TFXcan/imlab/shared/software/conda_envs/enformer-predict-tools/lib/python3.10/site-packages/parsl/dataflow/task_status_poller.py", line 110, in poll
    self._update_state()
  File "/lus/grand/projects/TFXcan/imlab/shared/software/conda_envs/enformer-predict-tools/lib/python3.10/site-packages/parsl/dataflow/task_status_poller.py", line 117, in _update_state
    item.poll(now)
  File "/lus/grand/projects/TFXcan/imlab/shared/software/conda_envs/enformer-predict-tools/lib/python3.10/site-packages/parsl/dataflow/task_status_poller.py", line 45, in poll
    self._status = self._executor.status()
  File "/lus/grand/projects/TFXcan/imlab/shared/software/conda_envs/enformer-predict-tools/lib/python3.10/site-packages/parsl/executors/status_handling.py", line 103, in status
    status = self._make_status_dict(block_ids, self._provider.status(job_ids))
  File "/lus/grand/projects/TFXcan/imlab/shared/software/conda_envs/enformer-predict-tools/lib/python3.10/site-packages/parsl/providers/cluster_provider.py", line 142, in status
    self._status()
  File "/lus/grand/projects/TFXcan/imlab/shared/software/conda_envs/enformer-predict-tools/lib/python3.10/site-packages/parsl/providers/torque/torque.py", line 132, in _status
    self.resources[job_id]['status'] = JobStatus(state)
KeyError: '483408.polaris-p*'
1681927336.695573 2023-04-19 18:02:16 MainProcess-136941 FlowControl-Thread-140008444544768 parsl.dataflow.flow_control:105 make_callback ERROR: Flow control callback threw an exception - logging and proceeding anyway
Traceback (most recent call last):
  File "/lus/grand/projects/TFXcan/imlab/shared/software/conda_envs/enformer-predict-tools/lib/python3.10/site-packages/parsl/dataflow/flow_control.py", line 103, in make_callback
    self.callback(tasks=self._event_buffer)
  File "/lus/grand/projects/TFXcan/imlab/shared/software/conda_envs/enformer-predict-tools/lib/python3.10/site-packages/parsl/dataflow/task_status_poller.py", line 110, in poll
    self._update_state()
  File "/lus/grand/projects/TFXcan/imlab/shared/software/conda_envs/enformer-predict-tools/lib/python3.10/site-packages/parsl/dataflow/task_status_poller.py", line 117, in _update_state
    item.poll(now)
  File "/lus/grand/projects/TFXcan/imlab/shared/software/conda_envs/enformer-predict-tools/lib/python3.10/site-packages/parsl/dataflow/task_status_poller.py", line 45, in poll
    self._status = self._executor.status()
  File "/lus/grand/projects/TFXcan/imlab/shared/software/conda_envs/enformer-predict-tools/lib/python3.10/site-packages/parsl/executors/status_handling.py", line 103, in status
    status = self._make_status_dict(block_ids, self._provider.status(job_ids))
  File "/lus/grand/projects/TFXcan/imlab/shared/software/conda_envs/enformer-predict-tools/lib/python3.10/site-packages/parsl/providers/cluster_provider.py", line 142, in status
    self._status()
  File "/lus/grand/projects/TFXcan/imlab/shared/software/conda_envs/enformer-predict-tools/lib/python3.10/site-packages/parsl/providers/torque/torque.py", line 132, in _status
    self.resources[job_id]['status'] = JobStatus(state)
KeyError: '483408.polaris-p*'
1681927341.704027 2023-04-19 18:02:21 MainProcess-136941 FlowControl-Thread-140008444544768 parsl.dataflow.flow_control:105 make_callback ERROR: Flow control callback threw an exception - logging and proceeding anyway
Traceback (most recent call last):
  File "/lus/grand/projects/TFXcan/imlab/shared/software/conda_envs/enformer-predict-tools/lib/python3.10/site-packages/parsl/dataflow/flow_control.py", line 103, in make_callback
    self.callback(tasks=self._event_buffer)
  File "/lus/grand/projects/TFXcan/imlab/shared/software/conda_envs/enformer-predict-tools/lib/python3.10/site-packages/parsl/dataflow/task_status_poller.py", line 110, in poll
    self._update_state()
  File "/lus/grand/projects/TFXcan/imlab/shared/software/conda_envs/enformer-predict-tools/lib/python3.10/site-packages/parsl/dataflow/task_status_poller.py", line 117, in _update_state
    item.poll(now)
  File "/lus/grand/projects/TFXcan/imlab/shared/software/conda_envs/enformer-predict-tools/lib/python3.10/site-packages/parsl/dataflow/task_status_poller.py", line 45, in poll
    self._status = self._executor.status()
  File "/lus/grand/projects/TFXcan/imlab/shared/software/conda_envs/enformer-predict-tools/lib/python3.10/site-packages/parsl/executors/status_handling.py", line 103, in status
    status = self._make_status_dict(block_ids, self._provider.status(job_ids))
  File "/lus/grand/projects/TFXcan/imlab/shared/software/conda_envs/enformer-predict-tools/lib/python3.10/site-packages/parsl/providers/cluster_provider.py", line 142, in status
    self._status()
  File "/lus/grand/projects/TFXcan/imlab/shared/software/conda_envs/enformer-predict-tools/lib/python3.10/site-packages/parsl/providers/torque/torque.py", line 132, in _status
    self.resources[job_id]['status'] = JobStatus(state)
KeyError: '483408.polaris-p*'
1681927346.696786 2023-04-19 18:02:26 MainProcess-136941 FlowControl-Thread-140008444544768 parsl.dataflow.flow_control:105 make_callback ERROR: Flow control callback threw an exception - logging and proceeding anyway
Traceback (most recent call last):
  File "/lus/grand/projects/TFXcan/imlab/shared/software/conda_envs/enformer-predict-tools/lib/python3.10/site-packages/parsl/dataflow/flow_control.py", line 103, in make_callback
    self.callback(tasks=self._event_buffer)
  File "/lus/grand/projects/TFXcan/imlab/shared/software/conda_envs/enformer-predict-tools/lib/python3.10/site-packages/parsl/dataflow/task_status_poller.py", line 110, in poll
    self._update_state()
  File "/lus/grand/projects/TFXcan/imlab/shared/software/conda_envs/enformer-predict-tools/lib/python3.10/site-packages/parsl/dataflow/task_status_poller.py", line 117, in _update_state
    item.poll(now)
  File "/lus/grand/projects/TFXcan/imlab/shared/software/conda_envs/enformer-predict-tools/lib/python3.10/site-packages/parsl/dataflow/task_status_poller.py", line 45, in poll
    self._status = self._executor.status()
  File "/lus/grand/projects/TFXcan/imlab/shared/software/conda_envs/enformer-predict-tools/lib/python3.10/site-packages/parsl/executors/status_handling.py", line 103, in status
    status = self._make_status_dict(block_ids, self._provider.status(job_ids))
  File "/lus/grand/projects/TFXcan/imlab/shared/software/conda_envs/enformer-predict-tools/lib/python3.10/site-packages/parsl/providers/cluster_provider.py", line 142, in status
    self._status()
  File "/lus/grand/projects/TFXcan/imlab/shared/software/conda_envs/enformer-predict-tools/lib/python3.10/site-packages/parsl/providers/torque/torque.py", line 132, in _status
    self.resources[job_id]['status'] = JobStatus(state)
KeyError: '483408.polaris-p*'
1681927351.696813 2023-04-19 18:02:31 MainProcess-136941 FlowControl-Thread-140008444544768 parsl.dataflow.flow_control:105 make_callback ERROR: Flow control callback threw an exception - logging and proceeding anyway
Traceback (most recent call last):
  File "/lus/grand/projects/TFXcan/imlab/shared/software/conda_envs/enformer-predict-tools/lib/python3.10/site-packages/parsl/dataflow/flow_control.py", line 103, in make_callback
    self.callback(tasks=self._event_buffer)
  File "/lus/grand/projects/TFXcan/imlab/shared/software/conda_envs/enformer-predict-tools/lib/python3.10/site-packages/parsl/dataflow/task_status_poller.py", line 110, in poll
    self._update_state()
  File "/lus/grand/projects/TFXcan/imlab/shared/software/conda_envs/enformer-predict-tools/lib/python3.10/site-packages/parsl/dataflow/task_status_poller.py", line 117, in _update_state
    item.poll(now)
  File "/lus/grand/projects/TFXcan/imlab/shared/software/conda_envs/enformer-predict-tools/lib/python3.10/site-packages/parsl/dataflow/task_status_poller.py", line 45, in poll
    self._status = self._executor.status()
  File "/lus/grand/projects/TFXcan/imlab/shared/software/conda_envs/enformer-predict-tools/lib/python3.10/site-packages/parsl/executors/status_handling.py", line 103, in status
    status = self._make_status_dict(block_ids, self._provider.status(job_ids))
  File "/lus/grand/projects/TFXcan/imlab/shared/software/conda_envs/enformer-predict-tools/lib/python3.10/site-packages/parsl/providers/cluster_provider.py", line 142, in status
    self._status()
  File "/lus/grand/projects/TFXcan/imlab/shared/software/conda_envs/enformer-predict-tools/lib/python3.10/site-packages/parsl/providers/torque/torque.py", line 132, in _status
    self.resources[job_id]['status'] = JobStatus(state)
KeyError: '483408.polaris-p*'
1681927356.696865 2023-04-19 18:02:36 MainProcess-136941 FlowControl-Thread-140008444544768 parsl.dataflow.flow_control:105 make_callback ERROR: Flow control callback threw an exception - logging and proceeding anyway
Traceback (most recent call last):
  File "/lus/grand/projects/TFXcan/imlab/shared/software/conda_envs/enformer-predict-tools/lib/python3.10/site-packages/parsl/dataflow/flow_control.py", line 103, in make_callback
    self.callback(tasks=self._event_buffer)
  File "/lus/grand/projects/TFXcan/imlab/shared/software/conda_envs/enformer-predict-tools/lib/python3.10/site-packages/parsl/dataflow/task_status_poller.py", line 110, in poll
    self._update_state()
  File "/lus/grand/projects/TFXcan/imlab/shared/software/conda_envs/enformer-predict-tools/lib/python3.10/site-packages/parsl/dataflow/task_status_poller.py", line 117, in _update_state
    item.poll(now)
  File "/lus/grand/projects/TFXcan/imlab/shared/software/conda_envs/enformer-predict-tools/lib/python3.10/site-packages/parsl/dataflow/task_status_poller.py", line 45, in poll
    self._status = self._executor.status()
  File "/lus/grand/projects/TFXcan/imlab/shared/software/conda_envs/enformer-predict-tools/lib/python3.10/site-packages/parsl/executors/status_handling.py", line 103, in status
    status = self._make_status_dict(block_ids, self._provider.status(job_ids))
  File "/lus/grand/projects/TFXcan/imlab/shared/software/conda_envs/enformer-predict-tools/lib/python3.10/site-packages/parsl/providers/cluster_provider.py", line 142, in status
    self._status()
  File "/lus/grand/projects/TFXcan/imlab/shared/software/conda_envs/enformer-predict-tools/lib/python3.10/site-packages/parsl/providers/torque/torque.py", line 132, in _status
    self.resources[job_id]['status'] = JobStatus(state)
KeyError: '483408.polaris-p*'
1681927361.702391 2023-04-19 18:02:41 MainProcess-136941 FlowControl-Thread-140008444544768 parsl.dataflow.flow_control:105 make_callback ERROR: Flow control callback threw an exception - logging and proceeding anyway
Traceback (most recent call last):
  File "/lus/grand/projects/TFXcan/imlab/shared/software/conda_envs/enformer-predict-tools/lib/python3.10/site-packages/parsl/dataflow/flow_control.py", line 103, in make_callback
    self.callback(tasks=self._event_buffer)
  File "/lus/grand/projects/TFXcan/imlab/shared/software/conda_envs/enformer-predict-tools/lib/python3.10/site-packages/parsl/dataflow/task_status_poller.py", line 110, in poll
    self._update_state()
  File "/lus/grand/projects/TFXcan/imlab/shared/software/conda_envs/enformer-predict-tools/lib/python3.10/site-packages/parsl/dataflow/task_status_poller.py", line 117, in _update_state
    item.poll(now)
  File "/lus/grand/projects/TFXcan/imlab/shared/software/conda_envs/enformer-predict-tools/lib/python3.10/site-packages/parsl/dataflow/task_status_poller.py", line 45, in poll
    self._status = self._executor.status()
  File "/lus/grand/projects/TFXcan/imlab/shared/software/conda_envs/enformer-predict-tools/lib/python3.10/site-packages/parsl/executors/status_handling.py", line 103, in status
    status = self._make_status_dict(block_ids, self._provider.status(job_ids))
  File "/lus/grand/projects/TFXcan/imlab/shared/software/conda_envs/enformer-predict-tools/lib/python3.10/site-packages/parsl/providers/cluster_provider.py", line 142, in status
    self._status()
  File "/lus/grand/projects/TFXcan/imlab/shared/software/conda_envs/enformer-predict-tools/lib/python3.10/site-packages/parsl/providers/torque/torque.py", line 132, in _status
    self.resources[job_id]['status'] = JobStatus(state)
KeyError: '483408.polaris-p*'
1681927366.701422 2023-04-19 18:02:46 MainProcess-136941 FlowControl-Thread-140008444544768 parsl.dataflow.flow_control:105 make_callback ERROR: Flow control callback threw an exception - logging and proceeding anyway
Traceback (most recent call last):
  File "/lus/grand/projects/TFXcan/imlab/shared/software/conda_envs/enformer-predict-tools/lib/python3.10/site-packages/parsl/dataflow/flow_control.py", line 103, in make_callback
    self.callback(tasks=self._event_buffer)
  File "/lus/grand/projects/TFXcan/imlab/shared/software/conda_envs/enformer-predict-tools/lib/python3.10/site-packages/parsl/dataflow/task_status_poller.py", line 110, in poll
    self._update_state()
  File "/lus/grand/projects/TFXcan/imlab/shared/software/conda_envs/enformer-predict-tools/lib/python3.10/site-packages/parsl/dataflow/task_status_poller.py", line 117, in _update_state
    item.poll(now)
  File "/lus/grand/projects/TFXcan/imlab/shared/software/conda_envs/enformer-predict-tools/lib/python3.10/site-packages/parsl/dataflow/task_status_poller.py", line 45, in poll
    self._status = self._executor.status()
  File "/lus/grand/projects/TFXcan/imlab/shared/software/conda_envs/enformer-predict-tools/lib/python3.10/site-packages/parsl/executors/status_handling.py", line 103, in status
    status = self._make_status_dict(block_ids, self._provider.status(job_ids))
  File "/lus/grand/projects/TFXcan/imlab/shared/software/conda_envs/enformer-predict-tools/lib/python3.10/site-packages/parsl/providers/cluster_provider.py", line 142, in status
    self._status()
  File "/lus/grand/projects/TFXcan/imlab/shared/software/conda_envs/enformer-predict-tools/lib/python3.10/site-packages/parsl/providers/torque/torque.py", line 132, in _status
    self.resources[job_id]['status'] = JobStatus(state)
KeyError: '483408.polaris-p*'
1681927371.695790 2023-04-19 18:02:51 MainProcess-136941 FlowControl-Thread-140008444544768 parsl.dataflow.flow_control:105 make_callback ERROR: Flow control callback threw an exception - logging and proceeding anyway
Traceback (most recent call last):
  File "/lus/grand/projects/TFXcan/imlab/shared/software/conda_envs/enformer-predict-tools/lib/python3.10/site-packages/parsl/dataflow/flow_control.py", line 103, in make_callback
    self.callback(tasks=self._event_buffer)
  File "/lus/grand/projects/TFXcan/imlab/shared/software/conda_envs/enformer-predict-tools/lib/python3.10/site-packages/parsl/dataflow/task_status_poller.py", line 110, in poll
    self._update_state()
  File "/lus/grand/projects/TFXcan/imlab/shared/software/conda_envs/enformer-predict-tools/lib/python3.10/site-packages/parsl/dataflow/task_status_poller.py", line 117, in _update_state
    item.poll(now)
  File "/lus/grand/projects/TFXcan/imlab/shared/software/conda_envs/enformer-predict-tools/lib/python3.10/site-packages/parsl/dataflow/task_status_poller.py", line 45, in poll
    self._status = self._executor.status()
  File "/lus/grand/projects/TFXcan/imlab/shared/software/conda_envs/enformer-predict-tools/lib/python3.10/site-packages/parsl/executors/status_handling.py", line 103, in status
    status = self._make_status_dict(block_ids, self._provider.status(job_ids))
  File "/lus/grand/projects/TFXcan/imlab/shared/software/conda_envs/enformer-predict-tools/lib/python3.10/site-packages/parsl/providers/cluster_provider.py", line 142, in status
    self._status()
  File "/lus/grand/projects/TFXcan/imlab/shared/software/conda_envs/enformer-predict-tools/lib/python3.10/site-packages/parsl/providers/torque/torque.py", line 132, in _status
    self.resources[job_id]['status'] = JobStatus(state)
KeyError: '483408.polaris-p*'
1681927376.700410 2023-04-19 18:02:56 MainProcess-136941 FlowControl-Thread-140008444544768 parsl.dataflow.flow_control:105 make_callback ERROR: Flow control callback threw an exception - logging and proceeding anyway
Traceback (most recent call last):
  File "/lus/grand/projects/TFXcan/imlab/shared/software/conda_envs/enformer-predict-tools/lib/python3.10/site-packages/parsl/dataflow/flow_control.py", line 103, in make_callback
    self.callback(tasks=self._event_buffer)
  File "/lus/grand/projects/TFXcan/imlab/shared/software/conda_envs/enformer-predict-tools/lib/python3.10/site-packages/parsl/dataflow/task_status_poller.py", line 110, in poll
    self._update_state()
  File "/lus/grand/projects/TFXcan/imlab/shared/software/conda_envs/enformer-predict-tools/lib/python3.10/site-packages/parsl/dataflow/task_status_poller.py", line 117, in _update_state
    item.poll(now)
  File "/lus/grand/projects/TFXcan/imlab/shared/software/conda_envs/enformer-predict-tools/lib/python3.10/site-packages/parsl/dataflow/task_status_poller.py", line 45, in poll
    self._status = self._executor.status()
  File "/lus/grand/projects/TFXcan/imlab/shared/software/conda_envs/enformer-predict-tools/lib/python3.10/site-packages/parsl/executors/status_handling.py", line 103, in status
    status = self._make_status_dict(block_ids, self._provider.status(job_ids))
  File "/lus/grand/projects/TFXcan/imlab/shared/software/conda_envs/enformer-predict-tools/lib/python3.10/site-packages/parsl/providers/cluster_provider.py", line 142, in status
    self._status()
  File "/lus/grand/projects/TFXcan/imlab/shared/software/conda_envs/enformer-predict-tools/lib/python3.10/site-packages/parsl/providers/torque/torque.py", line 132, in _status
    self.resources[job_id]['status'] = JobStatus(state)
KeyError: '483408.polaris-p*'
1681927381.700883 2023-04-19 18:03:01 MainProcess-136941 FlowControl-Thread-140008444544768 parsl.dataflow.flow_control:105 make_callback ERROR: Flow control callback threw an exception - logging and proceeding anyway
Traceback (most recent call last):
  File "/lus/grand/projects/TFXcan/imlab/shared/software/conda_envs/enformer-predict-tools/lib/python3.10/site-packages/parsl/dataflow/flow_control.py", line 103, in make_callback
    self.callback(tasks=self._event_buffer)
  File "/lus/grand/projects/TFXcan/imlab/shared/software/conda_envs/enformer-predict-tools/lib/python3.10/site-packages/parsl/dataflow/task_status_poller.py", line 110, in poll
    self._update_state()
  File "/lus/grand/projects/TFXcan/imlab/shared/software/conda_envs/enformer-predict-tools/lib/python3.10/site-packages/parsl/dataflow/task_status_poller.py", line 117, in _update_state
    item.poll(now)
  File "/lus/grand/projects/TFXcan/imlab/shared/software/conda_envs/enformer-predict-tools/lib/python3.10/site-packages/parsl/dataflow/task_status_poller.py", line 45, in poll
    self._status = self._executor.status()
  File "/lus/grand/projects/TFXcan/imlab/shared/software/conda_envs/enformer-predict-tools/lib/python3.10/site-packages/parsl/executors/status_handling.py", line 103, in status
    status = self._make_status_dict(block_ids, self._provider.status(job_ids))
  File "/lus/grand/projects/TFXcan/imlab/shared/software/conda_envs/enformer-predict-tools/lib/python3.10/site-packages/parsl/providers/cluster_provider.py", line 142, in status
    self._status()
  File "/lus/grand/projects/TFXcan/imlab/shared/software/conda_envs/enformer-predict-tools/lib/python3.10/site-packages/parsl/providers/torque/torque.py", line 132, in _status
    self.resources[job_id]['status'] = JobStatus(state)
KeyError: '483408.polaris-p*'
1681927386.723549 2023-04-19 18:03:06 MainProcess-136941 FlowControl-Thread-140008444544768 parsl.dataflow.flow_control:105 make_callback ERROR: Flow control callback threw an exception - logging and proceeding anyway
Traceback (most recent call last):
  File "/lus/grand/projects/TFXcan/imlab/shared/software/conda_envs/enformer-predict-tools/lib/python3.10/site-packages/parsl/dataflow/flow_control.py", line 103, in make_callback
    self.callback(tasks=self._event_buffer)
  File "/lus/grand/projects/TFXcan/imlab/shared/software/conda_envs/enformer-predict-tools/lib/python3.10/site-packages/parsl/dataflow/task_status_poller.py", line 110, in poll
    self._update_state()
  File "/lus/grand/projects/TFXcan/imlab/shared/software/conda_envs/enformer-predict-tools/lib/python3.10/site-packages/parsl/dataflow/task_status_poller.py", line 117, in _update_state
    item.poll(now)
  File "/lus/grand/projects/TFXcan/imlab/shared/software/conda_envs/enformer-predict-tools/lib/python3.10/site-packages/parsl/dataflow/task_status_poller.py", line 45, in poll
    self._status = self._executor.status()
  File "/lus/grand/projects/TFXcan/imlab/shared/software/conda_envs/enformer-predict-tools/lib/python3.10/site-packages/parsl/executors/status_handling.py", line 103, in status
    status = self._make_status_dict(block_ids, self._provider.status(job_ids))
  File "/lus/grand/projects/TFXcan/imlab/shared/software/conda_envs/enformer-predict-tools/lib/python3.10/site-packages/parsl/providers/cluster_provider.py", line 142, in status
    self._status()
  File "/lus/grand/projects/TFXcan/imlab/shared/software/conda_envs/enformer-predict-tools/lib/python3.10/site-packages/parsl/providers/torque/torque.py", line 132, in _status
    self.resources[job_id]['status'] = JobStatus(state)
KeyError: '483408.polaris-p*'
1681927390.530349 2023-04-19 18:03:10 MainProcess-136941 MainThread-140030062446400 parsl.dataflow.dflow:1028 atexit_cleanup INFO: DFK cleanup because python process is exiting
1681927390.558073 2023-04-19 18:03:10 MainProcess-136941 MainThread-140030062446400 parsl.dataflow.dflow:1066 cleanup INFO: DFK cleanup initiated
1681927390.559682 2023-04-19 18:03:10 MainProcess-136941 MainThread-140030062446400 parsl.dataflow.dflow:966 log_task_states INFO: Summary of tasks in DFK:
1681927390.560860 2023-04-19 18:03:10 MainProcess-136941 MainThread-140030062446400 parsl.dataflow.dflow:970 log_task_states INFO: Tasks in state States.unsched: 0
1681927390.562019 2023-04-19 18:03:10 MainProcess-136941 MainThread-140030062446400 parsl.dataflow.dflow:970 log_task_states INFO: Tasks in state States.pending: 0
1681927390.563149 2023-04-19 18:03:10 MainProcess-136941 MainThread-140030062446400 parsl.dataflow.dflow:970 log_task_states INFO: Tasks in state States.running: 0
1681927390.564240 2023-04-19 18:03:10 MainProcess-136941 MainThread-140030062446400 parsl.dataflow.dflow:970 log_task_states INFO: Tasks in state States.exec_done: 0
1681927390.565268 2023-04-19 18:03:10 MainProcess-136941 MainThread-140030062446400 parsl.dataflow.dflow:970 log_task_states INFO: Tasks in state States.failed: 0
1681927390.566317 2023-04-19 18:03:10 MainProcess-136941 MainThread-140030062446400 parsl.dataflow.dflow:970 log_task_states INFO: Tasks in state States.dep_fail: 0
1681927390.567396 2023-04-19 18:03:10 MainProcess-136941 MainThread-140030062446400 parsl.dataflow.dflow:970 log_task_states INFO: Tasks in state States.launched: 2
1681927390.568441 2023-04-19 18:03:10 MainProcess-136941 MainThread-140030062446400 parsl.dataflow.dflow:970 log_task_states INFO: Tasks in state States.fail_retryable: 0
1681927390.569530 2023-04-19 18:03:10 MainProcess-136941 MainThread-140030062446400 parsl.dataflow.dflow:970 log_task_states INFO: Tasks in state States.memo_done: 0
1681927390.570942 2023-04-19 18:03:10 MainProcess-136941 MainThread-140030062446400 parsl.dataflow.dflow:970 log_task_states INFO: Tasks in state States.joining: 0
1681927390.572896 2023-04-19 18:03:10 MainProcess-136941 MainThread-140030062446400 parsl.dataflow.dflow:970 log_task_states INFO: Tasks in state States.running_ended: 0
1681927390.573988 2023-04-19 18:03:10 MainProcess-136941 MainThread-140030062446400 parsl.dataflow.dflow:972 log_task_states INFO: End of summary
1681927390.575211 2023-04-19 18:03:10 MainProcess-136941 MainThread-140030062446400 parsl.dataflow.dflow:1090 cleanup INFO: Closing flowcontrol
1681927390.576607 2023-04-19 18:03:10 MainProcess-136941 MainThread-140030062446400 parsl.dataflow.dflow:1092 cleanup INFO: Terminated flow control
1681927390.577698 2023-04-19 18:03:10 MainProcess-136941 MainThread-140030062446400 parsl.dataflow.dflow:1094 cleanup INFO: Scaling in and shutting down executors
1681927390.578819 2023-04-19 18:03:10 MainProcess-136941 MainThread-140030062446400 parsl.dataflow.dflow:1099 cleanup INFO: Scaling in executor htex_PBS
1681927390.580459 2023-04-19 18:03:10 MainProcess-136941 MainThread-140030062446400 parsl.executors.high_throughput.executor:660 scale_in DEBUG: Scale in called, blocks=1, block_ids=[]
1681927390.582363 2023-04-19 18:03:10 MainProcess-136941 MainThread-140030062446400 parsl.executors.high_throughput.executor:676 scale_in DEBUG: Scale in selecting from 0 blocks
1681927390.602236 2023-04-19 18:03:10 MainProcess-136941 MainThread-140030062446400 parsl.dataflow.dflow:1109 cleanup INFO: Shutting down executor htex_PBS
1681927390.604219 2023-04-19 18:03:10 MainProcess-136941 MainThread-140030062446400 parsl.executors.high_throughput.executor:721 shutdown INFO: Attempting HighThroughputExecutor shutdown
1681927390.606182 2023-04-19 18:03:10 MainProcess-136941 MainThread-140030062446400 parsl.executors.high_throughput.executor:723 shutdown INFO: Finished HighThroughputExecutor shutdown attempt
1681927390.607369 2023-04-19 18:03:10 MainProcess-136941 MainThread-140030062446400 parsl.dataflow.dflow:1111 cleanup INFO: Shut down executor htex_PBS
1681927390.608539 2023-04-19 18:03:10 MainProcess-136941 MainThread-140030062446400 parsl.dataflow.dflow:1109 cleanup INFO: Shutting down executor _parsl_internal
1681927390.609674 2023-04-19 18:03:10 MainProcess-136941 MainThread-140030062446400 parsl.executors.threads:105 shutdown DEBUG: Shutting down executor, which involves waiting for running tasks to complete
1681927390.610837 2023-04-19 18:03:10 MainProcess-136941 MainThread-140030062446400 parsl.executors.threads:107 shutdown DEBUG: Done with executor shutdown
1681927390.611947 2023-04-19 18:03:10 MainProcess-136941 MainThread-140030062446400 parsl.dataflow.dflow:1111 cleanup INFO: Shut down executor _parsl_internal
1681927390.613264 2023-04-19 18:03:10 MainProcess-136941 MainThread-140030062446400 parsl.dataflow.dflow:1117 cleanup INFO: Terminated executors
1681927390.614696 2023-04-19 18:03:10 MainProcess-136941 MainThread-140030062446400 parsl.dataflow.dflow:1134 cleanup INFO: DFK cleanup complete
1681927390.615802 2023-04-19 18:03:10 MainProcess-136941 MainThread-140030062446400 parsl.process_loggers:28 wrapped DEBUG: Normal ending for cleanup on thread MainThread
